<?xml version="1.0" encoding="utf-8"?>
<!-- =================================================================================== -->
<!-- |    This document was autogenerated by xacro from panda_arm_hand.urdf.xacro      | -->
<!-- |    EDITING THIS FILE BY HAND IS NOT RECOMMENDED                                 | -->
<!-- =================================================================================== -->
<robot name="panda" xmlns:xacro="http://www.ros.org/wiki/xacro">
  <link name="root">
    <inertial>
      <mass value="0.01"/>
      <inertia ixx="1e-4" ixy="0.0" ixz="0.0" iyy="1e-4" iyz="0.0" izz="1e-4"/>
    </inertial>
  </link>
  <link name="root1">
    <inertial>
      <mass value="0.01"/>
      <inertia ixx="1e-4" ixy="0.0" ixz="0.0" iyy="1e-4" iyz="0.0" izz="1e-4"/>
    </inertial>
  </link>
  <link name="root2">
    <inertial>
      <mass value="0.01"/>
      <inertia ixx="1e-4" ixy="0.0" ixz="0.0" iyy="1e-4" iyz="0.0" izz="1e-4"/>
    </inertial>
  </link>
  <link name="root3">
    <inertial>
      <mass value="0.01"/>
      <inertia ixx="1e-4" ixy="0.0" ixz="0.0" iyy="1e-4" iyz="0.0" izz="1e-4"/>
    </inertial>
  </link>
  <link name="root4">
    <inertial>
      <mass value="0.01"/>
      <inertia ixx="1e-4" ixy="0.0" ixz="0.0" iyy="1e-4" iyz="0.0" izz="1e-4"/>
    </inertial>
  </link>
  <link name="root5">
    <inertial>
      <mass value="1"/>
      <inertia ixx="0.05" ixy="0.0" ixz="0.0" iyy="0.05" iyz="0.0" izz="0.05"/>
    </inertial>
  </link>
  <joint name="x_joint" type="prismatic">
    <parent link="root"/>
    <child link="root1"/>
    <axis xyz="1 0 0"/>
    <limit lower="-10" upper="10"/>
  </joint>
  <joint name="y_joint" type="prismatic">
    <parent link="root1"/>
    <child link="root2"/>
    <axis xyz="0 1 0"/>
    <limit lower="-10" upper="10"/>
  </joint>
  <joint name="z_joint" type="prismatic">
    <parent link="root2"/>
    <child link="root3"/>
    <axis xyz="0 0 1"/>
    <limit lower="-10" upper="10"/>
  </joint>
  <joint name="x_rotation_joint" type="continuous">
    <parent link="root3"/>
    <child link="root4"/>
    <axis xyz="1 0 0"/>
  </joint>
  <joint name="y_rotation_joint" type="continuous">
    <parent link="root4"/>
    <child link="root5"/>
    <axis xyz="0 1 0"/>
  </joint>
  <joint name="z_rotation_joint" type="continuous">
    <parent link="root5"/>
    <child link="panda_hand"/>
    <axis xyz="0 0 1"/>
  </joint>
  <link name="panda_hand">
    <visual>
      <geometry>
        <mesh filename="franka_description/meshes/visual/hand.dae"/>
      </geometry>
    </visual>
    <collision>
      <geometry>
        <mesh filename="franka_description/meshes/collision/hand.stl"/>
      </geometry>
    </collision>
  </link>
  <link name="panda_leftfinger">
    <visual>
      <geometry>
        <mesh filename="franka_description/meshes/visual/finger.dae"/>
      </geometry>
    </visual>
    <collision>
      <geometry>
        <mesh filename="franka_description/meshes/collision/finger.stl"/>
      </geometry>
    </collision>
  </link>
  <link name="panda_rightfinger">
    <visual>
      <origin rpy="0 0 3.14159265359" xyz="0 0 0"/>
      <geometry>
        <mesh filename="franka_description/meshes/visual/finger.dae"/>
      </geometry>
    </visual>
    <collision>
      <origin rpy="0 0 3.14159265359" xyz="0 0 0"/>
      <geometry>
        <mesh filename="franka_description/meshes/collision/finger.stl"/>
      </geometry>
    </collision>
  </link>
  <joint name="panda_finger_joint1" type="prismatic">
    <parent link="panda_hand"/>
    <child link="panda_leftfinger"/>
    <origin rpy="0 0 0" xyz="0 0 0.0584"/>
    <axis xyz="0 1 0"/>
    <limit effort="20" lower="0.0" upper="0.04" velocity="0.2"/>
  </joint>
  <joint name="panda_finger_joint2" type="prismatic">
    <parent link="panda_hand"/>
    <child link="panda_rightfinger"/>
    <origin rpy="0 0 0" xyz="0 0 0.0584"/>
    <axis xyz="0 -1 0"/>
    <limit effort="20" lower="0.0" upper="0.04" velocity="0.2"/>
    <mimic joint="panda_finger_joint1"/>
  </joint>
</robot>

